Workbook

Sheet Summary
A1: Order-to-Cash KPI catalogue
A2: 135 measures buildable today. Counts are live formulas over the KPI Catalogue tab.
A4: Folder | B4: Measures | C4: Core | D4: Standard | E4: What it covers
A5: 01 Base | B5: =COUNTIF('KPI Catalogue'!$B$2:$B$136,$A5) | C5: =COUNTIFS('KPI Catalogue'!$B$2:$B$136,$A5,'KPI Catalogue'!$G$2:$G$136,"Core") | D5: =COUNTIFS('KPI Catalogue'!$B$2:$B$136,$A5,'KPI Catalogue'!$G$2:$G$136,"Standard") | E5: Raw sums everything else builds on
A6: 02 Currency | B6: =COUNTIF('KPI Catalogue'!$B$2:$B$136,$A6) | C6: =COUNTIFS('KPI Catalogue'!$B$2:$B$136,$A6,'KPI Catalogue'!$G$2:$G$136,"Core") | D6: =COUNTIFS('KPI Catalogue'!$B$2:$B$136,$A6,'KPI Catalogue'!$G$2:$G$136,"Standard") | E6: FX coverage, quality flags and guards
A7: 03 Commercial | B7: =COUNTIF('KPI Catalogue'!$B$2:$B$136,$A7) | C7: =COUNTIFS('KPI Catalogue'!$B$2:$B$136,$A7,'KPI Catalogue'!$G$2:$G$136,"Core") | D7: =COUNTIFS('KPI Catalogue'!$B$2:$B$136,$A7,'KPI Catalogue'!$G$2:$G$136,"Standard") | E7: Price, revenue per line, time intelligence
A8: 04 Price Bridge | B8: =COUNTIF('KPI Catalogue'!$B$2:$B$136,$A8) | C8: =COUNTIFS('KPI Catalogue'!$B$2:$B$136,$A8,'KPI Catalogue'!$G$2:$G$136,"Core") | D8: =COUNTIFS('KPI Catalogue'!$B$2:$B$136,$A8,'KPI Catalogue'!$G$2:$G$136,"Standard") | E8: Commodity base and premium decomposition
A9: 05 Revenue Quality | B9: =COUNTIF('KPI Catalogue'!$B$2:$B$136,$A9) | C9: =COUNTIFS('KPI Catalogue'!$B$2:$B$136,$A9,'KPI Catalogue'!$G$2:$G$136,"Core") | D9: =COUNTIFS('KPI Catalogue'!$B$2:$B$136,$A9,'KPI Catalogue'!$G$2:$G$136,"Standard") | E9: Credit notes and billing accuracy
A10: 06 Order to Cash | B10: =COUNTIF('KPI Catalogue'!$B$2:$B$136,$A10) | C10: =COUNTIFS('KPI Catalogue'!$B$2:$B$136,$A10,'KPI Catalogue'!$G$2:$G$136,"Core") | D10: =COUNTIFS('KPI Catalogue'!$B$2:$B$136,$A10,'KPI Catalogue'!$G$2:$G$136,"Standard") | E10: Fulfilment, billing, backlog conversion
A11: 07 Service | B11: =COUNTIF('KPI Catalogue'!$B$2:$B$136,$A11) | C11: =COUNTIFS('KPI Catalogue'!$B$2:$B$136,$A11,'KPI Catalogue'!$G$2:$G$136,"Core") | D11: =COUNTIFS('KPI Catalogue'!$B$2:$B$136,$A11,'KPI Catalogue'!$G$2:$G$136,"Standard") | E11: On-time performance, cycle time, OTIF
A12: 08 Logistics | B12: =COUNTIF('KPI Catalogue'!$B$2:$B$136,$A12) | C12: =COUNTIFS('KPI Catalogue'!$B$2:$B$136,$A12,'KPI Catalogue'!$G$2:$G$136,"Core") | D12: =COUNTIFS('KPI Catalogue'!$B$2:$B$136,$A12,'KPI Catalogue'!$G$2:$G$136,"Standard") | E12: Deliveries, carriers, weight, export mix
A13: 09 Returns & Credits | B13: =COUNTIF('KPI Catalogue'!$B$2:$B$136,$A13) | C13: =COUNTIFS('KPI Catalogue'!$B$2:$B$136,$A13,'KPI Catalogue'!$G$2:$G$136,"Core") | D13: =COUNTIFS('KPI Catalogue'!$B$2:$B$136,$A13,'KPI Catalogue'!$G$2:$G$136,"Standard") | E13: Return volume, rate and root cause
A14: 10 Customer & Product | B14: =COUNTIF('KPI Catalogue'!$B$2:$B$136,$A14) | C14: =COUNTIFS('KPI Catalogue'!$B$2:$B$136,$A14,'KPI Catalogue'!$G$2:$G$136,"Core") | D14: =COUNTIFS('KPI Catalogue'!$B$2:$B$136,$A14,'KPI Catalogue'!$G$2:$G$136,"Standard") | E14: Concentration, ranking, Pareto
A15: 11 Data Quality | B15: =COUNTIF('KPI Catalogue'!$B$2:$B$136,$A15) | C15: =COUNTIFS('KPI Catalogue'!$B$2:$B$136,$A15,'KPI Catalogue'!$G$2:$G$136,"Core") | D15: =COUNTIFS('KPI Catalogue'!$B$2:$B$136,$A15,'KPI Catalogue'!$G$2:$G$136,"Standard") | E15: Model guard rails
A16: 12 Report Helpers | B16: =COUNTIF('KPI Catalogue'!$B$2:$B$136,$A16) | C16: =COUNTIFS('KPI Catalogue'!$B$2:$B$136,$A16,'KPI Catalogue'!$G$2:$G$136,"Core") | D16: =COUNTIFS('KPI Catalogue'!$B$2:$B$136,$A16,'KPI Catalogue'!$G$2:$G$136,"Standard") | E16: Dynamic titles and warnings
A17: Total | B17: =SUM(B5:B16) | C17: =SUM(C5:C16) | D17: =SUM(D5:D16)
A19: Blocked KPI families
A20: High impact | B20: =COUNTIF('Blocked KPIs'!$F$2:$F$15,LEFT($A20,SEARCH(" ",$A20)-1))
A21: Medium impact | B21: =COUNTIF('Blocked KPIs'!$F$2:$F$15,LEFT($A21,SEARCH(" ",$A21)-1))
A22: Low impact | B22: =COUNTIF('Blocked KPIs'!$F$2:$F$15,LEFT($A22,SEARCH(" ",$A22)-1))
A23: Resolved impact | B23: =COUNTIF('Blocked KPIs'!$F$2:$F$15,LEFT($A23,SEARCH(" ",$A23)-1))

Sheet KPI Catalogue
A1: ID | B1: Folder | C1: Measure | D1: What it tells you | E1: DAX | F1: Primary table | G1: Priority | H1: Format | I1: Sample (this extract)
A2: K-001 | B2: 01 Base | C2: Revenue USD | D2: Raw signed revenue. Everything downstream builds on this. | E2: SUM(fact_Invoice[Revenue_USD]) | F2: multiple | G2: Core | H2: \$#,0 | I2: $15.07bn
A3: K-002 | B3: 01 Base | C3: Gross Revenue USD | D3: Revenue before credit memos. | E3: CALCULATE([Revenue USD], fact_Invoice[Is_Credit_Memo] = FALSE()) | F3: multiple | G3: Core | H3: \$#,0 | I3: $15.30bn
A4: K-003 | B4: 01 Base | C4: Credits USD | D4: Credit memo value. Always negative. | E4: CALCULATE([Revenue USD], fact_Invoice[Is_Credit_Memo] = TRUE()) | F4: multiple | G4: Core | H4: \$#,0 | I4: -$229.8m
A5: K-004 | B5: 01 Base | C5: Net Revenue USD | D5: Revenue after credits. The headline number. | E5: [Gross Revenue USD] + [Credits USD] | F5: multiple | G5: Core | H5: \$#,0 | I5: $15.07bn
A6: K-005 | B6: 01 Base | C6: Ordered MT | D6: Signed ordered volume. Returns count negative. | E6: SUM(fact_SalesOrder[Ordered_MT_Signed]) | F6: multiple | G6: Core | H6: #,0 | I6: 25,346,201
A7: K-006 | B7: 01 Base | C7: Shipped MT | D7: Shipped volume from delivery details. | E7: SUM(fact_Shipment[Shipped_MT]) | F7: multiple | G7: Core | H7: #,0 | I7: 21,199,021
A8: K-007 | B8: 01 Base | C8: Shipped MT Order View | D8: Signed shipped volume on the order line. The correct partner for Ordered MT. | E8: SUM(fact_SalesOrder[Shipped_MT_Signed]) | F8: multiple | G8: Core | H8: #,0 | I8: 20,350,225
A9: K-008 | B9: 01 Base | C9: Invoiced MT | D9: Net billed volume. The two columns are mutually exclusive — both are required. | E9: SUM(fact_Invoice[Qty_Invoiced_MT]) + SUM(fact_Invoice[Qty_Credited_MT]) | F9: multiple | G9: Core | H9: #,0 | I9: 22,279,890
A10: K-009 | B10: 01 Base | C10: Order Lines | D10: Line count from the bridge. | E10: COUNTROWS(dim_SalesOrderLine) | F10: multiple | G10: Core | H10: #,0 | I10: 68,977
A11: K-010 | B11: 01 Base | C11: Invoice Lines | E11: COUNTROWS(fact_Invoice) | F11: multiple | G11: Core | H11: #,0 | I11: 79,576
A12: K-011 | B12: 01 Base | C12: Shipment Records | E12: COUNTROWS(fact_Shipment) | F12: multiple | G12: Core | H12: #,0 | I12: 84,505
A13: K-012 | B13: 01 Base | C13: Deliveries | E13: DISTINCTCOUNT(fact_Shipment[Delivery_Id]) | F13: multiple | G13: Core | H13: #,0 | I13: 59,947
A14: K-013 | B14: 01 Base | C14: Trips | E14: DISTINCTCOUNT(fact_Shipment[Trip_Id]) | F14: multiple | G14: Core | H14: #,0 | I14: 49,855
A15: K-014 | B15: 02 Currency | C15: Price Source Lines | D15: USD price came straight from the source. | E15: CALCULATE(COUNTROWS(fact_SalesOrder), fact_SalesOrder[Price_USD_Quality] = "1 - Source") | F15: fact_SalesOrder | G15: Core | H15: #,0 | I15: 60,685
A16: K-015 | B16: 02 Currency | C16: Price Converted Lines | D16: USD price computed from the three-tier rate hierarchy rather than supplied by the source. | E16: CALCULATE(COUNTROWS(fact_SalesOrder), fact_SalesOrder[Price_USD_Quality] = "2 - Converted") | F16: fact_SalesOrder | G16: Core | H16: #,0 | I16: 8,292
A17: K-016 | B17: 02 Currency | C17: Price Unconvertible Lines | D17: No usable USD price. Zero on the v2 extract — kept as a guard. | E17: CALCULATE(COUNTROWS(fact_SalesOrder), fact_SalesOrder[Price_USD_Quality] = "3 - Not convertible") | F17: fact_SalesOrder | G17: Core | H17: #,0 | I17: 0
A18: K-017 | B18: 02 Currency | C18: Price Coverage % | D18: Should read 100.000%. Put it on any page showing an average price. | E18: DIVIDE( [Price Source Lines] + [Price Converted Lines], COUNTROWS(fact_SalesOrder) ) | F18: fact_SalesOrder | G18: Core | H18: 0.0% | I18: 100.000%
A19: K-018 | B19: 02 Currency | C19: Currencies in Context | E19: DISTINCTCOUNT(dim_SalesOrderLine[Currency_Code]) | F19: fact_SalesOrder | G19: Core | H19: #,0 | I19: 9
A20: K-019 | B20: 02 Currency | C20: Avg Selling Price USD | D20: Never average the local-currency column — it mixes nine currencies and will always return a number. | E20: CALCULATE( AVERAGE(fact_SalesOrder[Unit_Selling_Price_USD]), fact_SalesOrder[Price_USD_Quality] <> "3 - Not convertible" ) | F20: fact_SalesOrder | G20: Core | H20: \$#,0.00 | I20: $2,234.19
A21: K-020 | B21: 02 Currency | C21: Avg Selling Price USD (Source Only) | D21: Same figure using no converted rows. Compare to prove the conversion is not shifting the answer. | E21: CALCULATE( AVERAGE(fact_SalesOrder[Unit_Selling_Price_USD]), fact_SalesOrder[Price_USD_Quality] = "1 - Source" ) | F21: fact_SalesOrder | G21: Core | H21: \$#,0.00 | I21: —
A22: K-021 | B22: 02 Currency | C22: Conversion Impact % | D22: Gap between the all-rows and source-only figures. If it is material, review the rate basis. | E22: DIVIDE( [Avg Selling Price USD] - [Avg Selling Price USD (Source Only)], [Avg Selling Price USD (Source Only)] ) | F22: fact_SalesOrder | G22: Core | H22: 0.00% | I22: —
A23: K-022 | B23: 02 Currency | C23: Applied FX Rate | D23: The Corporate rate actually applied, for audit. Blank when more than one currency is in context. | E23: IF( HASONEVALUE(dim_SalesOrderLine[CurrencyKey]), AVERAGE(fact_SalesOrder[FX_Rate]), BLANK() ) | F23: fact_SalesOrder | G23: Core | H23: #,0.00000 | I23: varies
A24: K-023 | B24: 02 Currency | C24: Currency Warning | D24: Fires when anything is missing or converted. Put it on the canvas of any price page. | E24: VAR Unconvertible = [Price Unconvertible Lines] VAR Coverage = [Price Coverage %] VAR Forward = [Forward Rate Lines] RETURN SWITCH( TRUE(), Unconvertible > 0, "! " & FORMAT(Unconvertible, "#,0") & " lines have no USD price and are excluded", Coverage < 1, "! Only " & FORMAT(Coverage, "0.000%") & " of lines have a usable USD price", Forward > 0, "i " & FORMAT(Forward, "#,0") & " lines valued at a carried-forward rate", BLANK() ) | F24: fact_SalesOrder | G24: Core | H24: text | I24: —
A25: K-024 | B25: 02 Currency | C25: Lines Priced at Shipment Date | D25: Conversion struck on the actual shipment date — realised, not forward-looking. | E25: CALCULATE(COUNTROWS(fact_SalesOrder), fact_SalesOrder[FX_Date_Basis] = "2 - Actual shipment") | F25: fact_SalesOrder | G25: Core | H25: #,0 | I25: 30,617
A26: K-025 | B26: 02 Currency | C26: FX Date Basis Fallback % | D26: Share of rows converted on a forward date because the line has not shipped yet. | E26: DIVIDE( CALCULATE( COUNTROWS(fact_SalesOrder), NOT fact_SalesOrder[FX_Date_Basis] IN { "1 - Source Exchange_Date", "2 - Actual shipment", "3 - Fulfilment" } ), COUNTROWS(fact_SalesOrder) ) | F26: fact_SalesOrder | G26: Core | H26: 0.0% | I26: 5.3%
A27: K-026 | B27: 02 Currency | C27: USC Lines | D27: Dolar Compra lines. Resolved 1:1 with USD by the rate table — kept visible because the code is unusual. | E27: CALCULATE(COUNTROWS(fact_SalesOrder), RELATED(dim_Currency[Currency_Code]) = "USC") | F27: fact_SalesOrder | G27: Core | H27: #,0 | I27: 2,976
A28: K-027 | B28: 02 Currency | C28: Lines at Source Rate | D28: Rows using the rate the source itself supplied. It reproduces the USD price exactly. | E28: CALCULATE(COUNTROWS(fact_SalesOrder), fact_SalesOrder[FX_Rate_Source] = "Source Exchange_Rate") | F28: fact_SalesOrder | G28: Core | H28: #,0 | I28: 30,541
A29: K-028 | B29: 02 Currency | C29: Lines at Table Rate | D29: Rows converted by looking the rate up in d_exchange_rate. The only tier that can be forward. | E29: CALCULATE(COUNTROWS(fact_SalesOrder), fact_SalesOrder[FX_Rate_Source] = "Corporate rate table") | F29: fact_SalesOrder | G29: Core | H29: #,0 | I29: 5,316
A30: K-029 | B30: 02 Currency | C30: Lines at Identity Rate | D30: USD and USC rows. No conversion applied. | E30: CALCULATE(COUNTROWS(fact_SalesOrder), fact_SalesOrder[FX_Rate_Source] = "Identity (USD/USC)") | F30: fact_SalesOrder | G30: Core | H30: #,0 | I30: 33,120
A31: K-030 | B31: 11 Data Quality | C31: Unresolved Rate Lines | D31: Must be zero. Anything here means a currency-region pair is missing from d_exchange_rate. | E31: CALCULATE(COUNTROWS(fact_SalesOrder), fact_SalesOrder[FX_Rate_Source] = "Unresolved") | F31: multiple | G31: Core | H31: #,0 | I31: 0
... A38: K-037 | B38: 03 Commercial | C38: Realised Price per MT | D38: Net revenue per tonne billed. The cleanest commercial measure in the model. | E38: DIVIDE([Net Revenue USD], [Invoiced MT]) | F38: fact_Invoice | G38: Core | H38: \$#,0.00 | I38: $676.40
A39: K-038 | B39: 03 Commercial | C39: Revenue per Order Line | E39: DIVIDE([Net Revenue USD], [Order Lines]) | F39: fact_Invoice | G39: Core | H39: \$#,0 | I39: $220,102
A40: K-039 | B40: 03 Commercial | C40: Revenue by Invoice Date | D40: Activates the inactive invoice-date relationship. Finance will want this view. | E40: CALCULATE( [Net Revenue USD], USERELATIONSHIP(dim_Date[Date], fact_Invoice[Invoice_Date]) ) | F40: fact_Invoice | G40: Core | H40: \$#,0 | I40: —
A41: K-040 | B41: 03 Commercial | C41: Revenue YTD | E41: TOTALYTD([Revenue by Invoice Date], dim_Date[Date]) | F41: fact_Invoice | G41: Core | H41: \$#,0 | I41: —
A42: K-041 | B42: 03 Commercial | C42: Revenue PM | E42: CALCULATE([Revenue by Invoice Date], PREVIOUSMONTH(dim_Date[Date])) | F42: fact_Invoice | G42: Core | H42: \$#,0 | I42: —
A43: K-042 | B43: 03 Commercial | C43: Revenue MoM % | E43: DIVIDE([Revenue by Invoice Date] - [Revenue PM], [Revenue PM]) | F43: fact_Invoice | G43: Core | H43: 0.0% | I43: —
A44: K-043 | B44: 03 Commercial | C44: Revenue R3M Avg | D44: Smooths the monthly noise. | E44: CALCULATE( AVERAGEX(VALUES(dim_Date[Year_Month_Sort]), [Revenue by Invoice Date]), DATESINPERIOD(dim_Date[Date], MAX(dim_Date[Date]), -3, MONTH) ) | F44: fact_Invoice | G44: Core | H44: \$#,0 | I44: —
A45: K-044 | B45: 03 Commercial | C45: Realised Price PM | E45: CALCULATE([Realised Price per MT], PREVIOUSMONTH(dim_Date[Date])) | F45: fact_Invoice | G45: Core | H45: \$#,0.00 | I45: —
A46: K-045 | B46: 03 Commercial | C46: Realised Price MoM % | E46: DIVIDE([Realised Price per MT] - [Realised Price PM], [Realised Price PM]) | F46: fact_Invoice | G46: Core | H46: 0.0% | I46: —
...

Sheet Blocked KPIs
A1: ID | B1: Domain | C1: What it would measure | D1: Why it is blocked | E1: What would unblock it | F1: Impact
A2: BLK-00 | B2: Currency | C2: RESOLVED - USC and full FX coverage | D2: d_exchange_rate resolves USC as 1:1 with USD, and the v2 query supplies Exchange_Rate directly. Coverage is 100.000%. | E2: Closed - no action needed. | F2: Resolved
A3: BLK-00b | B3: Data quality | C3: RESOLVED - WHERE clause precedence | D3: Fixed in the v2 sales order query. Cancelled lines went 39 to 0 and the extract grew to 68,977. | E3: Apply the same brackets to the invoice and shipment queries. | F3: Resolved
A4: BLK-01 | B4: Revenue & Commercial | C4: Gross margin / contribution per tonne | D4: No cost data of any kind in the three facts — no COGS, standard cost or freight cost. | E4: Add a cost fact at item x plant x month. Standard cost alone unlocks the whole margin family. | F4: High
A5: BLK-02 | B5: Finance | C5: DSO, overdue balances, cash collection | D5: No payment or settlement records. Term_Name gives the agreed term but nothing confirms collection. | E5: Requires an AR ledger or payments fact keyed on invoice. | F5: High
A6: BLK-03 | B6: Logistics | C6: Freight cost per tonne / cost per lane | D6: No freight rate or carrier cost columns anywhere in f_Shipment. | E6: Join freight invoices or a rate card on carrier x lane. | F6: High
A7: BLK-04 | B7: Service | C7: Actual transit time door to door | D7: Trip stop actual arrival and actual departure carry identical timestamps — computed transit is 0.00 days across 63,969 rows. | E7: Needs genuine event capture at pickup and drop-off. Use delay-against-plan as the proxy meanwhile. | F7: High
A8: BLK-05 | B8: Returns | C8: Link a credit back to the original sale | D8: Line_DFF_Quick_RMA_Original_Line_Id is populated on 8 rows and none of the 8 resolve to any Line_Id. | E8: Source-side fix. Without it credit root-cause cannot reach the original transaction. | F8: High
A9: BLK-06 | B9: Commercial | C9: Year-on-year growth | D9: The extract starts January 2026. 99.7% of invoice rows are 2026. | E9: Extend the source query window. The model already supports it. | F9: High
A10: BLK-08 | B10: Logistics | C10: Vessel / voyage reliability | D10: Voyage columns are 0.1-0.4% populated (117 to 337 rows of 84,505). | E10: Backfill voyage data, or scope the metric to ocean shipments only. | F10: Medium
A11: BLK-09 | B11: Logistics | C11: Container utilisation / fill rate | D11: Delivery_Detail_LPN_Container_Name is 3.6% populated; Trip_DFF_Container_Number is 0%. | E11: Capture container assignment on every containerised delivery. | F11: Medium
A12: BLK-10 | B12: Service | C12: Delivered and received volume | D12: Delivered_Qty_MT, Received_Qty_MT and Scheduled_Qty_MT are populated but every value is zero across all 84,505 clean rows. | E12: Ask whether delivery confirmation is captured at all. If it is, the ETL is not carrying it. | F12: High
... A15: BLK-13 | B15: Forecasting | C15: Forecast accuracy / plan vs actual | D15: No forecast or budget data in scope. | E15: Add a forecast fact at customer x product x month. | F15: Medium
